<?xml version="1.0" ?>
<sdf version="1.9">
  <world name="warehouse">

    <!-- Physics -->
    <physics name="1ms" type="dart">
      <max_step_size>0.001</max_step_size>
      <real_time_factor>1.0</real_time_factor>
    </physics>

    <!-- Plugins -->
    <plugin filename="gz-sim-physics-system" name="gz::sim::systems::Physics"/>
    <plugin filename="gz-sim-scene-broadcaster-system" name="gz::sim::systems::SceneBroadcaster"/>
    <plugin filename="gz-sim-sensors-system" name="gz::sim::systems::Sensors">
      <render_engine>ogre2</render_engine>
    </plugin>
    <plugin filename="gz-sim-user-commands-system" name="gz::sim::systems::UserCommands"/>

    <!-- Lighting -->
    <light type="directional" name="warehouse_light">
      <cast_shadows>true</cast_shadows>
      <pose>0 0 5 0 0 0</pose>
      <diffuse>0.9 0.9 0.9 1</diffuse>
      <specular>0.3 0.3 0.3 1</specular>
      <direction>-0.5 0.1 -0.9</direction>
    </light>

    <light type="point" name="fill_light">
      <pose>0 0 3 0 0 0</pose>
      <diffuse>0.4 0.4 0.4 1</diffuse>
      <specular>0.1 0.1 0.1 1</specular>
      <attenuation>
        <range>10</range>
        <constant>0.5</constant>
        <linear>0.01</linear>
        <quadratic>0.001</quadratic>
      </attenuation>
    </light>

    <!-- Ground plane -->
    <model name="ground_plane">
      <static>true</static>
      <link name="link">
        <collision name="collision">
          <geometry>
            <plane><normal>0 0 1</normal><size>10 10</size></plane>
          </geometry>
        </collision>
        <visual name="visual">
          <geometry>
            <plane><normal>0 0 1</normal><size>10 10</size></plane>
          </geometry>
          <material>
            <ambient>0.6 0.6 0.6 1</ambient>
            <diffuse>0.6 0.6 0.6 1</diffuse>
          </material>
        </visual>
      </link>
    </model>

    <!-- ==================== SHELF A ==================== -->
    <model name="shelf_A">
      <static>true</static>
      <pose>2.0 0.0 0.0 0 0 0</pose>
      <link name="shelf_body">
        <!-- Left side panel -->
        <visual name="left_panel">
          <pose>0 -0.3 0.5 0 0 0</pose>
          <geometry><box><size>0.4 0.02 1.0</size></box></geometry>
          <material><ambient>0.5 0.3 0.1 1</ambient><diffuse>0.6 0.4 0.2 1</diffuse></material>
        </visual>
        <collision name="left_panel_col">
          <pose>0 -0.3 0.5 0 0 0</pose>
          <geometry><box><size>0.4 0.02 1.0</size></box></geometry>
        </collision>
        <!-- Right side panel -->
        <visual name="right_panel">
          <pose>0 0.3 0.5 0 0 0</pose>
          <geometry><box><size>0.4 0.02 1.0</size></box></geometry>
          <material><ambient>0.5 0.3 0.1 1</ambient><diffuse>0.6 0.4 0.2 1</diffuse></material>
        </visual>
        <collision name="right_panel_col">
          <pose>0 0.3 0.5 0 0 0</pose>
          <geometry><box><size>0.4 0.02 1.0</size></box></geometry>
        </collision>
        <!-- Shelf surface -->
        <visual name="shelf_surface">
          <pose>0 0 0.4 0 0 0</pose>
          <geometry><box><size>0.4 0.6 0.02</size></box></geometry>
          <material><ambient>0.5 0.3 0.1 1</ambient><diffuse>0.6 0.4 0.2 1</diffuse></material>
        </visual>
        <collision name="shelf_surface_col">
          <pose>0 0 0.4 0 0 0</pose>
          <geometry><box><size>0.4 0.6 0.02</size></box></geometry>
        </collision>
      </link>
    </model>

    <!-- ==================== SHELF B ==================== -->
    <model name="shelf_B">
      <static>true</static>
      <pose>2.0 2.0 0.0 0 0 0</pose>
      <link name="shelf_body">
        <visual name="left_panel">
          <pose>0 -0.3 0.5 0 0 0</pose>
          <geometry><box><size>0.4 0.02 1.0</size></box></geometry>
          <material><ambient>0.5 0.3 0.1 1</ambient><diffuse>0.6 0.4 0.2 1</diffuse></material>
        </visual>
        <collision name="left_panel_col">
          <pose>0 -0.3 0.5 0 0 0</pose>
          <geometry><box><size>0.4 0.02 1.0</size></box></geometry>
        </collision>
        <visual name="right_panel">
          <pose>0 0.3 0.5 0 0 0</pose>
          <geometry><box><size>0.4 0.02 1.0</size></box></geometry>
          <material><ambient>0.5 0.3 0.1 1</ambient><diffuse>0.6 0.4 0.2 1</diffuse></material>
        </visual>
        <collision name="right_panel_col">
          <pose>0 0.3 0.5 0 0 0</pose>
          <geometry><box><size>0.4 0.02 1.0</size></box></geometry>
        </collision>
        <visual name="shelf_surface">
          <pose>0 0 0.4 0 0 0</pose>
          <geometry><box><size>0.4 0.6 0.02</size></box></geometry>
          <material><ambient>0.5 0.3 0.1 1</ambient><diffuse>0.6 0.4 0.2 1</diffuse></material>
        </visual>
        <collision name="shelf_surface_col">
          <pose>0 0 0.4 0 0 0</pose>
          <geometry><box><size>0.4 0.6 0.02</size></box></geometry>
        </collision>
      </link>
    </model>

    <!-- ==================== SHELF C ==================== -->
    <model name="shelf_C">
      <static>true</static>
      <pose>2.0 -2.0 0.0 0 0 0</pose>
      <link name="shelf_body">
        <visual name="left_panel">
          <pose>0 -0.3 0.5 0 0 0</pose>
          <geometry><box><size>0.4 0.02 1.0</size></box></geometry>
          <material><ambient>0.5 0.3 0.1 1</ambient><diffuse>0.6 0.4 0.2 1</diffuse></material>
        </visual>
        <collision name="left_panel_col">
          <pose>0 -0.3 0.5 0 0 0</pose>
          <geometry><box><size>0.4 0.02 1.0</size></box></geometry>
        </collision>
        <visual name="right_panel">
          <pose>0 0.3 0.5 0 0 0</pose>
          <geometry><box><size>0.4 0.02 1.0</size></box></geometry>
          <material><ambient>0.5 0.3 0.1 1</ambient><diffuse>0.6 0.4 0.2 1</diffuse></material>
        </visual>
        <collision name="right_panel_col">
          <pose>0 0.3 0.5 0 0 0</pose>
          <geometry><box><size>0.4 0.02 1.0</size></box></geometry>
        </collision>
        <visual name="shelf_surface">
          <pose>0 0 0.4 0 0 0</pose>
          <geometry><box><size>0.4 0.6 0.02</size></box></geometry>
          <material><ambient>0.5 0.3 0.1 1</ambient><diffuse>0.6 0.4 0.2 1</diffuse></material>
        </visual>
        <collision name="shelf_surface_col">
          <pose>0 0 0.4 0 0 0</pose>
          <geometry><box><size>0.4 0.6 0.02</size></box></geometry>
        </collision>
      </link>
    </model>

    <!-- ==================== OBJECTS ==================== -->

    <!-- Apple (red sphere) on Shelf A slot 0 -->
    <model name="apple">
      <pose>2.0 -0.1 0.45 0 0 0</pose>
      <link name="link">
        <inertial>
          <mass>0.2</mass>
          <inertia>
            <ixx>0.000128</ixx><iyy>0.000128</iyy><izz>0.000128</izz>
          </inertia>
        </inertial>
        <collision name="collision">
          <geometry><sphere><radius>0.04</radius></sphere></geometry>
          <surface>
            <friction><ode><mu>0.8</mu><mu2>0.8</mu2></ode></friction>
          </surface>
        </collision>
        <visual name="visual">
          <geometry><sphere><radius>0.04</radius></sphere></geometry>
          <material><ambient>1.0 0.0 0.0 1</ambient><diffuse>1.0 0.1 0.1 1</diffuse></material>
        </visual>
      </link>
    </model>

    <!-- Bottle (blue cylinder) on Shelf A slot 1 -->
    <model name="bottle">
      <pose>2.0 0.1 0.485 0 0 0</pose>
      <link name="link">
        <inertial>
          <mass>0.3</mass>
          <inertia>
            <ixx>0.000338</ixx><iyy>0.000338</iyy><izz>0.000135</izz>
          </inertia>
        </inertial>
        <collision name="collision">
          <geometry><cylinder><radius>0.03</radius><length>0.15</length></cylinder></geometry>
          <surface>
            <friction><ode><mu>0.6</mu><mu2>0.6</mu2></ode></friction>
          </surface>
        </collision>
        <visual name="visual">
          <geometry><cylinder><radius>0.03</radius><length>0.15</length></cylinder></geometry>
          <material><ambient>0.0 0.5 1.0 1</ambient><diffuse>0.1 0.5 1.0 1</diffuse></material>
        </visual>
      </link>
    </model>

    <!-- Book (green box) on Shelf B slot 0 -->
    <model name="book">
      <pose>2.0 1.9 0.425 0 0 0</pose>
      <link name="link">
        <inertial>
          <mass>0.4</mass>
          <inertia>
            <ixx>0.000347</ixx><iyy>0.000817</iyy><izz>0.001067</izz>
          </inertia>
        </inertial>
        <collision name="collision">
          <geometry><box><size>0.15 0.10 0.03</size></box></geometry>
          <surface>
            <friction><ode><mu>0.7</mu><mu2>0.7</mu2></ode></friction>
          </surface>
        </collision>
        <visual name="visual">
          <geometry><box><size>0.15 0.10 0.03</size></box></geometry>
          <material><ambient>0.0 0.7 0.0 1</ambient><diffuse>0.1 0.8 0.1 1</diffuse></material>
        </visual>
      </link>
    </model>

    <!-- Box (brown box) on Shelf B slot 1 -->
    <model name="box">
      <pose>2.0 2.1 0.46 0 0 0</pose>
      <link name="link">
        <inertial>
          <mass>0.5</mass>
          <inertia>
            <ixx>0.000833</ixx><iyy>0.000833</iyy><izz>0.000833</izz>
          </inertia>
        </inertial>
        <collision name="collision">
          <geometry><box><size>0.10 0.10 0.10</size></box></geometry>
          <surface>
            <friction><ode><mu>0.7</mu><mu2>0.7</mu2></ode></friction>
          </surface>
        </collision>
        <visual name="visual">
          <geometry><box><size>0.10 0.10 0.10</size></box></geometry>
          <material><ambient>0.8 0.6 0.2 1</ambient><diffuse>0.8 0.6 0.2 1</diffuse></material>
        </visual>
      </link>
    </model>

    <!-- Can (silver cylinder) on Shelf C slot 0 -->
    <model name="can">
      <pose>2.0 -2.1 0.47 0 0 0</pose>
      <link name="link">
        <inertial>
          <mass>0.35</mass>
          <inertia>
            <ixx>0.000223</ixx><iyy>0.000223</iyy><izz>0.000158</izz>
          </inertia>
        </inertial>
        <collision name="collision">
          <geometry><cylinder><radius>0.03</radius><length>0.12</length></cylinder></geometry>
          <surface>
            <friction><ode><mu>0.5</mu><mu2>0.5</mu2></ode></friction>
          </surface>
        </collision>
        <visual name="visual">
          <geometry><cylinder><radius>0.03</radius><length>0.12</length></cylinder></geometry>
          <material><ambient>0.8 0.8 0.8 1</ambient><diffuse>0.9 0.9 0.9 1</diffuse></material>
        </visual>
      </link>
    </model>

    <!-- Cup (white cylinder) on Shelf C slot 1 -->
    <model name="cup">
      <pose>2.0 -1.9 0.46 0 0 0</pose>
      <link name="link">
        <inertial>
          <mass>0.15</mass>
          <inertia>
            <ixx>0.000100</ixx><iyy>0.000100</iyy><izz>0.000120</izz>
          </inertia>
        </inertial>
        <collision name="collision">
          <geometry><cylinder><radius>0.04</radius><length>0.10</length></cylinder></geometry>
          <surface>
            <friction><ode><mu>0.6</mu><mu2>0.6</mu2></ode></friction>
          </surface>
        </collision>
        <visual name="visual">
          <geometry><cylinder><radius>0.04</radius><length>0.10</length></cylinder></geometry>
          <material><ambient>1.0 1.0 1.0 1</ambient><diffuse>1.0 1.0 1.0 1</diffuse></material>
        </visual>
      </link>
    </model>

    <!-- ==================== COLLECTION BOX ==================== -->
    <model name="collection_box">
      <static>true</static>
      <pose>-1.0 0.0 0.0 0 0 0</pose>
      <link name="link">
        <!-- Bottom -->
        <visual name="bottom">
          <pose>0 0 0.01 0 0 0</pose>
          <geometry><box><size>0.5 0.5 0.02</size></box></geometry>
          <material><ambient>0.3 0.3 0.3 1</ambient><diffuse>0.4 0.4 0.4 1</diffuse></material>
        </visual>
        <collision name="bottom_col">
          <pose>0 0 0.01 0 0 0</pose>
          <geometry><box><size>0.5 0.5 0.02</size></box></geometry>
        </collision>
        <!-- Front wall -->
        <visual name="front_wall">
          <pose>0.25 0 0.15 0 0 0</pose>
          <geometry><box><size>0.02 0.5 0.3</size></box></geometry>
          <material><ambient>0.3 0.3 0.3 1</ambient><diffuse>0.4 0.4 0.4 1</diffuse></material>
        </visual>
        <collision name="front_wall_col">
          <pose>0.25 0 0.15 0 0 0</pose>
          <geometry><box><size>0.02 0.5 0.3</size></box></geometry>
        </collision>
        <!-- Back wall -->
        <visual name="back_wall">
          <pose>-0.25 0 0.15 0 0 0</pose>
          <geometry><box><size>0.02 0.5 0.3</size></box></geometry>
          <material><ambient>0.3 0.3 0.3 1</ambient><diffuse>0.4 0.4 0.4 1</diffuse></material>
        </visual>
        <collision name="back_wall_col">
          <pose>-0.25 0 0.15 0 0 0</pose>
          <geometry><box><size>0.02 0.5 0.3</size></box></geometry>
        </collision>
        <!-- Left wall -->
        <visual name="left_wall">
          <pose>0 -0.25 0.15 0 0 0</pose>
          <geometry><box><size>0.5 0.02 0.3</size></box></geometry>
          <material><ambient>0.3 0.3 0.3 1</ambient><diffuse>0.4 0.4 0.4 1</diffuse></material>
        </visual>
        <collision name="left_wall_col">
          <pose>0 -0.25 0.15 0 0 0</pose>
          <geometry><box><size>0.5 0.02 0.3</size></box></geometry>
        </collision>
        <!-- Right wall -->
        <visual name="right_wall">
          <pose>0 0.25 0.15 0 0 0</pose>
          <geometry><box><size>0.5 0.02 0.3</size></box></geometry>
          <material><ambient>0.3 0.3 0.3 1</ambient><diffuse>0.4 0.4 0.4 1</diffuse></material>
        </visual>
        <collision name="right_wall_col">
          <pose>0 0.25 0.15 0 0 0</pose>
          <geometry><box><size>0.5 0.02 0.3</size></box></geometry>
        </collision>
      </link>
    </model>

    <!-- ==================== ROBOT ARM (Simplified 6-DOF) ==================== -->
    <model name="panda_arm">
      <pose>0.0 0.0 0.0 0 0 0</pose>

      <!-- Base -->
      <link name="base_link">
        <inertial>
          <mass>5.0</mass>
          <inertia>
            <ixx>0.01</ixx><iyy>0.01</iyy><izz>0.01</izz>
          </inertia>
        </inertial>
        <visual name="base_visual">
          <geometry><cylinder><radius>0.08</radius><length>0.05</length></cylinder></geometry>
          <material><ambient>0.2 0.2 0.2 1</ambient><diffuse>0.3 0.3 0.3 1</diffuse></material>
        </visual>
        <collision name="base_collision">
          <geometry><cylinder><radius>0.08</radius><length>0.05</length></cylinder></geometry>
        </collision>
      </link>

      <!-- Link 1 -->
      <link name="link1">
        <pose relative_to="joint1"/>
        <inertial>
          <pose>0 0 0.15 0 0 0</pose>
          <mass>2.0</mass>
          <inertia>
            <ixx>0.01</ixx><iyy>0.01</iyy><izz>0.002</izz>
          </inertia>
        </inertial>
        <visual name="visual">
          <pose>0 0 0.15 0 0 0</pose>
          <geometry><cylinder><radius>0.04</radius><length>0.3</length></cylinder></geometry>
          <material><ambient>0.9 0.9 0.9 1</ambient><diffuse>0.95 0.95 0.95 1</diffuse></material>
        </visual>
        <collision name="collision">
          <pose>0 0 0.15 0 0 0</pose>
          <geometry><cylinder><radius>0.04</radius><length>0.3</length></cylinder></geometry>
        </collision>
      </link>

      <joint name="joint1" type="revolute">
        <parent>base_link</parent>
        <child>link1</child>
        <pose>0 0 0.05 0 0 0</pose>
        <axis>
          <xyz>0 0 1</xyz>
          <limit><lower>-2.8973</lower><upper>2.8973</upper><effort>87</effort><velocity>2.175</velocity></limit>
        </axis>
      </joint>

      <!-- Link 2 -->
      <link name="link2">
        <pose relative_to="joint2"/>
        <inertial>
          <pose>0 0 0.15 0 0 0</pose>
          <mass>2.0</mass>
          <inertia>
            <ixx>0.01</ixx><iyy>0.01</iyy><izz>0.002</izz>
          </inertia>
        </inertial>
        <visual name="visual">
          <pose>0 0 0.15 0 0 0</pose>
          <geometry><cylinder><radius>0.04</radius><length>0.3</length></cylinder></geometry>
          <material><ambient>0.9 0.9 0.9 1</ambient><diffuse>0.95 0.95 0.95 1</diffuse></material>
        </visual>
        <collision name="collision">
          <pose>0 0 0.15 0 0 0</pose>
          <geometry><cylinder><radius>0.04</radius><length>0.3</length></cylinder></geometry>
        </collision>
      </link>

      <joint name="joint2" type="revolute">
        <parent>link1</parent>
        <child>link2</child>
        <pose>0 0 0.3 0 0 0</pose>
        <axis>
          <xyz>0 1 0</xyz>
          <limit><lower>-1.7628</lower><upper>1.7628</upper><effort>87</effort><velocity>2.175</velocity></limit>
        </axis>
      </joint>

      <!-- Link 3 -->
      <link name="link3">
        <pose relative_to="joint3"/>
        <inertial>
          <pose>0 0 0.1 0 0 0</pose>
          <mass>1.5</mass>
          <inertia>
            <ixx>0.005</ixx><iyy>0.005</iyy><izz>0.001</izz>
          </inertia>
        </inertial>
        <visual name="visual">
          <pose>0 0 0.1 0 0 0</pose>
          <geometry><cylinder><radius>0.035</radius><length>0.2</length></cylinder></geometry>
          <material><ambient>0.9 0.9 0.9 1</ambient><diffuse>0.95 0.95 0.95 1</diffuse></material>
        </visual>
        <collision name="collision">
          <pose>0 0 0.1 0 0 0</pose>
          <geometry><cylinder><radius>0.035</radius><length>0.2</length></cylinder></geometry>
        </collision>
      </link>

      <joint name="joint3" type="revolute">
        <parent>link2</parent>
        <child>link3</child>
        <pose>0 0 0.3 0 0 0</pose>
        <axis>
          <xyz>0 0 1</xyz>
          <limit><lower>-2.8973</lower><upper>2.8973</upper><effort>87</effort><velocity>2.175</velocity></limit>
        </axis>
      </joint>

      <!-- Link 4 -->
      <link name="link4">
        <pose relative_to="joint4"/>
        <inertial>
          <pose>0 0 0.1 0 0 0</pose>
          <mass>1.5</mass>
          <inertia>
            <ixx>0.005</ixx><iyy>0.005</iyy><izz>0.001</izz>
          </inertia>
        </inertial>
        <visual name="visual">
          <pose>0 0 0.1 0 0 0</pose>
          <geometry><cylinder><radius>0.035</radius><length>0.2</length></cylinder></geometry>
          <material><ambient>0.9 0.9 0.9 1</ambient><diffuse>0.95 0.95 0.95 1</diffuse></material>
        </visual>
        <collision name="collision">
          <pose>0 0 0.1 0 0 0</pose>
          <geometry><cylinder><radius>0.035</radius><length>0.2</length></cylinder></geometry>
        </collision>
      </link>

      <joint name="joint4" type="revolute">
        <parent>link3</parent>
        <child>link4</child>
        <pose>0 0 0.2 0 0 0</pose>
        <axis>
          <xyz>0 1 0</xyz>
          <limit><lower>-3.0718</lower><upper>-0.0698</upper><effort>87</effort><velocity>2.175</velocity></limit>
        </axis>
      </joint>

      <!-- Link 5 -->
      <link name="link5">
        <pose relative_to="joint5"/>
        <inertial>
          <pose>0 0 0.075 0 0 0</pose>
          <mass>1.0</mass>
          <inertia>
            <ixx>0.003</ixx><iyy>0.003</iyy><izz>0.001</izz>
          </inertia>
        </inertial>
        <visual name="visual">
          <pose>0 0 0.075 0 0 0</pose>
          <geometry><cylinder><radius>0.03</radius><length>0.15</length></cylinder></geometry>
          <material><ambient>0.9 0.9 0.9 1</ambient><diffuse>0.95 0.95 0.95 1</diffuse></material>
        </visual>
        <collision name="collision">
          <pose>0 0 0.075 0 0 0</pose>
          <geometry><cylinder><radius>0.03</radius><length>0.15</length></cylinder></geometry>
        </collision>
      </link>

      <joint name="joint5" type="revolute">
        <parent>link4</parent>
        <child>link5</child>
        <pose>0 0 0.2 0 0 0</pose>
        <axis>
          <xyz>0 0 1</xyz>
          <limit><lower>-2.8973</lower><upper>2.8973</upper><effort>12</effort><velocity>2.61</velocity></limit>
        </axis>
      </joint>

      <!-- Link 6 (end-effector mount) -->
      <link name="link6">
        <pose relative_to="joint6"/>
        <inertial>
          <pose>0 0 0.05 0 0 0</pose>
          <mass>0.5</mass>
          <inertia>
            <ixx>0.001</ixx><iyy>0.001</iyy><izz>0.0005</izz>
          </inertia>
        </inertial>
        <visual name="visual">
          <pose>0 0 0.05 0 0 0</pose>
          <geometry><cylinder><radius>0.025</radius><length>0.1</length></cylinder></geometry>
          <material><ambient>0.3 0.3 0.3 1</ambient><diffuse>0.4 0.4 0.4 1</diffuse></material>
        </visual>
        <collision name="collision">
          <pose>0 0 0.05 0 0 0</pose>
          <geometry><cylinder><radius>0.025</radius><length>0.1</length></cylinder></geometry>
        </collision>
      </link>

      <joint name="joint6" type="revolute">
        <parent>link5</parent>
        <child>link6</child>
        <pose>0 0 0.15 0 0 0</pose>
        <axis>
          <xyz>0 1 0</xyz>
          <limit><lower>-0.0175</lower><upper>3.7525</upper><effort>12</effort><velocity>2.61</velocity></limit>
        </axis>
      </joint>

      <!-- Gripper (simplified as a prismatic joint pair) -->
      <link name="gripper_left">
        <pose relative_to="gripper_joint_left"/>
        <inertial>
          <mass>0.1</mass>
          <inertia>
            <ixx>0.0001</ixx><iyy>0.0001</iyy><izz>0.0001</izz>
          </inertia>
        </inertial>
        <visual name="visual">
          <geometry><box><size>0.01 0.02 0.06</size></box></geometry>
          <material><ambient>0.5 0.5 0.5 1</ambient><diffuse>0.6 0.6 0.6 1</diffuse></material>
        </visual>
        <collision name="collision">
          <geometry><box><size>0.01 0.02 0.06</size></box></geometry>
        </collision>
      </link>

      <joint name="gripper_joint_left" type="prismatic">
        <parent>link6</parent>
        <child>gripper_left</child>
        <pose>0 -0.02 0.1 0 0 0</pose>
        <axis>
          <xyz>0 1 0</xyz>
          <limit><lower>0</lower><upper>0.04</upper><effort>20</effort><velocity>0.2</velocity></limit>
        </axis>
      </joint>

      <link name="gripper_right">
        <pose relative_to="gripper_joint_right"/>
        <inertial>
          <mass>0.1</mass>
          <inertia>
            <ixx>0.0001</ixx><iyy>0.0001</iyy><izz>0.0001</izz>
          </inertia>
        </inertial>
        <visual name="visual">
          <geometry><box><size>0.01 0.02 0.06</size></box></geometry>
          <material><ambient>0.5 0.5 0.5 1</ambient><diffuse>0.6 0.6 0.6 1</diffuse></material>
        </visual>
        <collision name="collision">
          <geometry><box><size>0.01 0.02 0.06</size></box></geometry>
        </collision>
      </link>

      <joint name="gripper_joint_right" type="prismatic">
        <parent>link6</parent>
        <child>gripper_right</child>
        <pose>0 0.02 0.1 0 0 0</pose>
        <axis>
          <xyz>0 -1 0</xyz>
          <limit><lower>0</lower><upper>0.04</upper><effort>20</effort><velocity>0.2</velocity></limit>
        </axis>
      </joint>

      <!-- Joint position controller plugin -->
      <plugin filename="gz-sim-joint-position-controller-system"
              name="gz::sim::systems::JointPositionController">
        <joint_name>joint1</joint_name>
        <p_gain>100</p_gain>
        <i_gain>0.1</i_gain>
        <d_gain>10</d_gain>
      </plugin>
      <plugin filename="gz-sim-joint-position-controller-system"
              name="gz::sim::systems::JointPositionController">
        <joint_name>joint2</joint_name>
        <p_gain>100</p_gain>
        <i_gain>0.1</i_gain>
        <d_gain>10</d_gain>
      </plugin>
      <plugin filename="gz-sim-joint-position-controller-system"
              name="gz::sim::systems::JointPositionController">
        <joint_name>joint3</joint_name>
        <p_gain>100</p_gain>
        <i_gain>0.1</i_gain>
        <d_gain>10</d_gain>
      </plugin>
      <plugin filename="gz-sim-joint-position-controller-system"
              name="gz::sim::systems::JointPositionController">
        <joint_name>joint4</joint_name>
        <p_gain>100</p_gain>
        <i_gain>0.1</i_gain>
        <d_gain>10</d_gain>
      </plugin>
      <plugin filename="gz-sim-joint-position-controller-system"
              name="gz::sim::systems::JointPositionController">
        <joint_name>joint5</joint_name>
        <p_gain>50</p_gain>
        <i_gain>0.1</i_gain>
        <d_gain>5</d_gain>
      </plugin>
      <plugin filename="gz-sim-joint-position-controller-system"
              name="gz::sim::systems::JointPositionController">
        <joint_name>joint6</joint_name>
        <p_gain>50</p_gain>
        <i_gain>0.1</i_gain>
        <d_gain>5</d_gain>
      </plugin>
      <plugin filename="gz-sim-joint-position-controller-system"
              name="gz::sim::systems::JointPositionController">
        <joint_name>gripper_joint_left</joint_name>
        <p_gain>100</p_gain>
        <i_gain>0.1</i_gain>
        <d_gain>1</d_gain>
      </plugin>
      <plugin filename="gz-sim-joint-position-controller-system"
              name="gz::sim::systems::JointPositionController">
        <joint_name>gripper_joint_right</joint_name>
        <p_gain>100</p_gain>
        <i_gain>0.1</i_gain>
        <d_gain>1</d_gain>
      </plugin>

      <!-- Joint state publisher -->
      <plugin filename="gz-sim-joint-state-publisher-system"
              name="gz::sim::systems::JointStatePublisher"/>
    </model>

    <!-- ==================== OVERHEAD CAMERA ==================== -->
    <model name="overhead_camera">
      <static>true</static>
      <pose>1.0 0.0 3.0 0 1.5708 0</pose>
      <link name="link">
        <visual name="visual">
          <geometry><box><size>0.05 0.05 0.05</size></box></geometry>
          <material><ambient>0 0 0 1</ambient><diffuse>0.1 0.1 0.1 1</diffuse></material>
        </visual>
        <sensor name="camera" type="camera">
          <always_on>1</always_on>
          <update_rate>30</update_rate>
          <camera>
            <horizontal_fov>1.5708</horizontal_fov>
            <image>
              <width>640</width>
              <height>480</height>
              <format>R8G8B8</format>
            </image>
            <clip>
              <near>0.1</near>
              <far>10</far>
            </clip>
          </camera>
          <topic>camera</topic>
        </sensor>
      </link>
    </model>

  </world>
</sdf>
